[2024-10-25 12:51:52,764][__main__][INFO] - Instantiating datamodule <src.datamodules.dogbreed.CatDogDataModule>
[2024-10-25 12:51:52,767][__main__][ERROR] - Error instantiating datamodule
Traceback (most recent call last):
  File "/venv/lib/python3.9/site-packages/hydra/_internal/utils.py", line 639, in _locate
    obj = getattr(obj, part)
AttributeError: module 'src.datamodules' has no attribute 'dogbreed'

During handling of the above exception, another exception occurred:

Traceback (most recent call last):
  File "/venv/lib/python3.9/site-packages/hydra/_internal/utils.py", line 645, in _locate
    obj = import_module(mod)
  File "/usr/local/lib/python3.9/importlib/__init__.py", line 127, in import_module
    return _bootstrap._gcd_import(name[level:], package, level)
  File "<frozen importlib._bootstrap>", line 1030, in _gcd_import
  File "<frozen importlib._bootstrap>", line 1007, in _find_and_load
  File "<frozen importlib._bootstrap>", line 984, in _find_and_load_unlocked
ModuleNotFoundError: No module named 'src.datamodules.dogbreed'

The above exception was the direct cause of the following exception:

Traceback (most recent call last):
  File "/venv/lib/python3.9/site-packages/hydra/_internal/instantiate/_instantiate2.py", line 134, in _resolve_target
    target = _locate(target)
  File "/venv/lib/python3.9/site-packages/hydra/_internal/utils.py", line 648, in _locate
    raise ImportError(
ImportError: Error loading 'src.datamodules.dogbreed.CatDogDataModule':
ModuleNotFoundError("No module named 'src.datamodules.dogbreed'")
Are you sure that 'dogbreed' is importable from module 'src.datamodules'?

The above exception was the direct cause of the following exception:

Traceback (most recent call last):
  File "/code/src/train.py", line 150, in main
    datamodule: L.LightningDataModule = hydra.utils.instantiate(cfg.data)
  File "/venv/lib/python3.9/site-packages/hydra/_internal/instantiate/_instantiate2.py", line 222, in instantiate
    return instantiate_node(
  File "/venv/lib/python3.9/site-packages/hydra/_internal/instantiate/_instantiate2.py", line 325, in instantiate_node
    _target_ = _resolve_target(node.get(_Keys.TARGET), full_key)
  File "/venv/lib/python3.9/site-packages/hydra/_internal/instantiate/_instantiate2.py", line 139, in _resolve_target
    raise InstantiationException(msg) from e
hydra.errors.InstantiationException: Error locating target 'src.datamodules.dogbreed.CatDogDataModule', see chained exception above.
full_key: data
